[2023-12-20T19:45:13.077+0000] {taskinstance.py:1957} INFO - Dependencies all met for dep_context=non-requeueable deps ti=<TaskInstance: ETL_redshift_docker_airflow.extraer_data manual__2023-12-20T19:45:11.302518+00:00 [queued]>
[2023-12-20T19:45:13.090+0000] {taskinstance.py:1957} INFO - Dependencies all met for dep_context=requeueable deps ti=<TaskInstance: ETL_redshift_docker_airflow.extraer_data manual__2023-12-20T19:45:11.302518+00:00 [queued]>
[2023-12-20T19:45:13.090+0000] {taskinstance.py:2171} INFO - Starting attempt 1 of 6
[2023-12-20T19:45:13.146+0000] {taskinstance.py:2192} INFO - Executing <Task(PythonOperator): extraer_data> on 2023-12-20 19:45:11.302518+00:00
[2023-12-20T19:45:13.152+0000] {standard_task_runner.py:60} INFO - Started process 1193 to run task
[2023-12-20T19:45:13.155+0000] {standard_task_runner.py:87} INFO - Running: ['***', 'tasks', 'run', 'ETL_redshift_docker_***', 'extraer_data', 'manual__2023-12-20T19:45:11.302518+00:00', '--job-id', '283', '--raw', '--subdir', 'DAGS_FOLDER/ETL a Redshift.py', '--cfg-path', '/tmp/tmpoqu5bn16']
[2023-12-20T19:45:13.157+0000] {standard_task_runner.py:88} INFO - Job 283: Subtask extraer_data
[2023-12-20T19:45:13.171+0000] {warnings.py:109} WARNING - /home/***/.local/lib/python3.8/site-packages/***/settings.py:195: DeprecationWarning: The sql_alchemy_conn option in [core] has been moved to the sql_alchemy_conn option in [database] - the old setting has been used, but please update your config.
  SQL_ALCHEMY_CONN = conf.get("database", "SQL_ALCHEMY_CONN")

[2023-12-20T19:45:13.206+0000] {task_command.py:423} INFO - Running <TaskInstance: ETL_redshift_docker_airflow.extraer_data manual__2023-12-20T19:45:11.302518+00:00 [running]> on host de1b3d441485
[2023-12-20T19:45:13.255+0000] {warnings.py:109} WARNING - /home/***/.local/lib/python3.8/site-packages/***/utils/context.py:207: AirflowContextDeprecationWarning: Accessing 'execution_date' from the template is deprecated and will be removed in a future version. Please use 'data_interval_start' or 'logical_date' instead.
  warnings.warn(_create_deprecation_warning(key, self._deprecation_replacements[key]))

[2023-12-20T19:45:13.289+0000] {taskinstance.py:2481} INFO - Exporting env vars: AIRFLOW_CTX_DAG_OWNER='ManuelMoyano' AIRFLOW_CTX_DAG_ID='ETL_redshift_docker_***' AIRFLOW_CTX_TASK_ID='extraer_data' AIRFLOW_CTX_EXECUTION_DATE='2023-12-20T19:45:11.302518+00:00' AIRFLOW_CTX_TRY_NUMBER='1' AIRFLOW_CTX_DAG_RUN_ID='manual__2023-12-20T19:45:11.302518+00:00'
[2023-12-20T19:45:13.291+0000] {logging_mixin.py:188} INFO - Adquiriendo data para la fecha: 2023-12-20 19
[2023-12-20T19:45:34.403+0000] {taskinstance.py:2699} ERROR - Task failed with exception
Traceback (most recent call last):
  File "/home/airflow/.local/lib/python3.8/site-packages/urllib3/connectionpool.py", line 715, in urlopen
    httplib_response = self._make_request(
  File "/home/airflow/.local/lib/python3.8/site-packages/urllib3/connectionpool.py", line 404, in _make_request
    self._validate_conn(conn)
  File "/home/airflow/.local/lib/python3.8/site-packages/urllib3/connectionpool.py", line 1058, in _validate_conn
    conn.connect()
  File "/home/airflow/.local/lib/python3.8/site-packages/urllib3/connection.py", line 419, in connect
    self.sock = ssl_wrap_socket(
  File "/home/airflow/.local/lib/python3.8/site-packages/urllib3/util/ssl_.py", line 449, in ssl_wrap_socket
    ssl_sock = _ssl_wrap_socket_impl(
  File "/home/airflow/.local/lib/python3.8/site-packages/urllib3/util/ssl_.py", line 493, in _ssl_wrap_socket_impl
    return ssl_context.wrap_socket(sock, server_hostname=server_hostname)
  File "/usr/local/lib/python3.8/ssl.py", line 500, in wrap_socket
    return self.sslsocket_class._create(
  File "/usr/local/lib/python3.8/ssl.py", line 1073, in _create
    self.do_handshake()
  File "/usr/local/lib/python3.8/ssl.py", line 1342, in do_handshake
    self._sslobj.do_handshake()
ssl.SSLZeroReturnError: TLS/SSL connection has been closed (EOF) (_ssl.c:1131)

During handling of the above exception, another exception occurred:

Traceback (most recent call last):
  File "/home/airflow/.local/lib/python3.8/site-packages/requests/adapters.py", line 486, in send
    resp = conn.urlopen(
  File "/home/airflow/.local/lib/python3.8/site-packages/urllib3/connectionpool.py", line 799, in urlopen
    retries = retries.increment(
  File "/home/airflow/.local/lib/python3.8/site-packages/urllib3/util/retry.py", line 592, in increment
    raise MaxRetryError(_pool, url, error or ResponseError(cause))
urllib3.exceptions.MaxRetryError: HTTPSConnectionPool(host='api.themoviedb.org', port=443): Max retries exceeded with url: /3/trending/movie/day?api_key=256fcaa48a42faf31d52b502826de42e&page=1 (Caused by SSLError(SSLZeroReturnError(6, 'TLS/SSL connection has been closed (EOF) (_ssl.c:1131)')))

During handling of the above exception, another exception occurred:

Traceback (most recent call last):
  File "/home/airflow/.local/lib/python3.8/site-packages/airflow/models/taskinstance.py", line 433, in _execute_task
    result = execute_callable(context=context, **execute_callable_kwargs)
  File "/home/airflow/.local/lib/python3.8/site-packages/airflow/operators/python.py", line 199, in execute
    return_value = self.execute_callable()
  File "/home/airflow/.local/lib/python3.8/site-packages/airflow/operators/python.py", line 216, in execute_callable
    return self.python_callable(*self.op_args, **self.op_kwargs)
  File "/opt/airflow/dags/ETL a Redshift.py", line 77, in extraer_data
    response_movie = requests.get(url_movie, params=params, headers=headers)
  File "/home/airflow/.local/lib/python3.8/site-packages/requests/api.py", line 73, in get
    return request("get", url, params=params, **kwargs)
  File "/home/airflow/.local/lib/python3.8/site-packages/requests/api.py", line 59, in request
    return session.request(method=method, url=url, **kwargs)
  File "/home/airflow/.local/lib/python3.8/site-packages/requests/sessions.py", line 589, in request
    resp = self.send(prep, **send_kwargs)
  File "/home/airflow/.local/lib/python3.8/site-packages/requests/sessions.py", line 703, in send
    r = adapter.send(request, **kwargs)
  File "/home/airflow/.local/lib/python3.8/site-packages/requests/adapters.py", line 517, in send
    raise SSLError(e, request=request)
requests.exceptions.SSLError: HTTPSConnectionPool(host='api.themoviedb.org', port=443): Max retries exceeded with url: /3/trending/movie/day?api_key=256fcaa48a42faf31d52b502826de42e&page=1 (Caused by SSLError(SSLZeroReturnError(6, 'TLS/SSL connection has been closed (EOF) (_ssl.c:1131)')))
[2023-12-20T19:45:34.420+0000] {taskinstance.py:1138} INFO - Marking task as UP_FOR_RETRY. dag_id=ETL_redshift_docker_***, task_id=extraer_data, execution_date=20231220T194511, start_date=20231220T194513, end_date=20231220T194534
[2023-12-20T19:45:34.448+0000] {standard_task_runner.py:107} ERROR - Failed to execute job 283 for task extraer_data (HTTPSConnectionPool(host='api.themoviedb.org', port=443): Max retries exceeded with url: /3/trending/movie/day?api_key=256fcaa48a42faf31d52b502826de42e&page=1 (Caused by SSLError(SSLZeroReturnError(6, 'TLS/SSL connection has been closed (EOF) (_ssl.c:1131)'))); 1193)
[2023-12-20T19:45:34.500+0000] {local_task_job_runner.py:234} INFO - Task exited with return code 1
[2023-12-20T19:45:34.530+0000] {taskinstance.py:3281} INFO - 0 downstream tasks scheduled from follow-on schedule check
