[2023-12-06 11:28:16,344] {taskinstance.py:1179} INFO - Dependencies all met for <TaskInstance: ETL_redshift_docker_airflow.transformar_data scheduled__2023-12-05T00:00:00+00:00 [queued]>
[2023-12-06 11:28:16,354] {taskinstance.py:1179} INFO - Dependencies all met for <TaskInstance: ETL_redshift_docker_airflow.transformar_data scheduled__2023-12-05T00:00:00+00:00 [queued]>
[2023-12-06 11:28:16,355] {taskinstance.py:1376} INFO - 
--------------------------------------------------------------------------------
[2023-12-06 11:28:16,355] {taskinstance.py:1377} INFO - Starting attempt 2 of 6
[2023-12-06 11:28:16,356] {taskinstance.py:1378} INFO - 
--------------------------------------------------------------------------------
[2023-12-06 11:28:16,369] {taskinstance.py:1397} INFO - Executing <Task(PythonOperator): transformar_data> on 2023-12-05 00:00:00+00:00
[2023-12-06 11:28:16,373] {standard_task_runner.py:52} INFO - Started process 403 to run task
[2023-12-06 11:28:16,376] {standard_task_runner.py:79} INFO - Running: ['***', 'tasks', 'run', 'ETL_redshift_docker_***', 'transformar_data', 'scheduled__2023-12-05T00:00:00+00:00', '--job-id', '24', '--raw', '--subdir', 'DAGS_FOLDER/ETL a Redshift.py', '--cfg-path', '/tmp/tmpds6jz6aw', '--error-file', '/tmp/tmpyr79mpw9']
[2023-12-06 11:28:16,377] {standard_task_runner.py:80} INFO - Job 24: Subtask transformar_data
[2023-12-06 11:28:16,436] {task_command.py:371} INFO - Running <TaskInstance: ETL_redshift_docker_airflow.transformar_data scheduled__2023-12-05T00:00:00+00:00 [running]> on host 4357a10b93bd
[2023-12-06 11:28:16,474] {logging_mixin.py:115} WARNING - /home/***/.local/lib/python3.7/site-packages/***/utils/context.py:202 AirflowContextDeprecationWarning: Accessing 'execution_date' from the template is deprecated and will be removed in a future version. Please use 'data_interval_start' or 'logical_date' instead.
[2023-12-06 11:28:16,510] {taskinstance.py:1591} INFO - Exporting the following env vars:
AIRFLOW_CTX_DAG_OWNER=ManuelMoyano
AIRFLOW_CTX_DAG_ID=ETL_redshift_docker_***
AIRFLOW_CTX_TASK_ID=transformar_data
AIRFLOW_CTX_EXECUTION_DATE=2023-12-05T00:00:00+00:00
AIRFLOW_CTX_TRY_NUMBER=2
AIRFLOW_CTX_DAG_RUN_ID=scheduled__2023-12-05T00:00:00+00:00
[2023-12-06 11:28:16,513] {logging_mixin.py:115} INFO - Transformando la data para la fecha: 2023-12-05 0
[2023-12-06 11:28:16,513] {taskinstance.py:1909} ERROR - Task failed with exception
Traceback (most recent call last):
  File "/home/airflow/.local/lib/python3.7/site-packages/airflow/operators/python.py", line 171, in execute
    return_value = self.execute_callable()
  File "/home/airflow/.local/lib/python3.7/site-packages/airflow/operators/python.py", line 189, in execute_callable
    return self.python_callable(*self.op_args, **self.op_kwargs)
  File "/opt/airflow/dags/ETL a Redshift.py", line 101, in transformar_data
    fullpage_movie = pages[f'df_movie_{1}']
KeyError: 'df_movie_1'
[2023-12-06 11:28:16,523] {taskinstance.py:1420} INFO - Marking task as UP_FOR_RETRY. dag_id=ETL_redshift_docker_***, task_id=transformar_data, execution_date=20231205T000000, start_date=20231206T112816, end_date=20231206T112816
[2023-12-06 11:28:16,534] {standard_task_runner.py:97} ERROR - Failed to execute job 24 for task transformar_data ('df_movie_1'; 403)
[2023-12-06 11:28:16,547] {local_task_job.py:156} INFO - Task exited with return code 1
[2023-12-06 11:28:16,597] {local_task_job.py:273} INFO - 0 downstream tasks scheduled from follow-on schedule check
[2023-12-06 18:41:29,940] {taskinstance.py:1179} INFO - Dependencies all met for <TaskInstance: ETL_redshift_docker_airflow.transformar_data scheduled__2023-12-05T00:00:00+00:00 [queued]>
[2023-12-06 18:41:29,950] {taskinstance.py:1179} INFO - Dependencies all met for <TaskInstance: ETL_redshift_docker_airflow.transformar_data scheduled__2023-12-05T00:00:00+00:00 [queued]>
[2023-12-06 18:41:29,950] {taskinstance.py:1376} INFO - 
--------------------------------------------------------------------------------
[2023-12-06 18:41:29,950] {taskinstance.py:1377} INFO - Starting attempt 2 of 6
[2023-12-06 18:41:29,951] {taskinstance.py:1378} INFO - 
--------------------------------------------------------------------------------
[2023-12-06 18:41:29,965] {taskinstance.py:1397} INFO - Executing <Task(PythonOperator): transformar_data> on 2023-12-05 00:00:00+00:00
[2023-12-06 18:41:29,969] {standard_task_runner.py:52} INFO - Started process 388 to run task
[2023-12-06 18:41:29,972] {standard_task_runner.py:79} INFO - Running: ['***', 'tasks', 'run', 'ETL_redshift_docker_***', 'transformar_data', 'scheduled__2023-12-05T00:00:00+00:00', '--job-id', '50', '--raw', '--subdir', 'DAGS_FOLDER/ETL a Redshift.py', '--cfg-path', '/tmp/tmp0bm4cbj1', '--error-file', '/tmp/tmpgaxa819z']
[2023-12-06 18:41:29,974] {standard_task_runner.py:80} INFO - Job 50: Subtask transformar_data
[2023-12-06 18:41:30,034] {task_command.py:371} INFO - Running <TaskInstance: ETL_redshift_docker_airflow.transformar_data scheduled__2023-12-05T00:00:00+00:00 [running]> on host 4357a10b93bd
[2023-12-06 18:41:30,075] {logging_mixin.py:115} WARNING - /home/***/.local/lib/python3.7/site-packages/***/utils/context.py:202 AirflowContextDeprecationWarning: Accessing 'execution_date' from the template is deprecated and will be removed in a future version. Please use 'data_interval_start' or 'logical_date' instead.
[2023-12-06 18:41:30,110] {taskinstance.py:1591} INFO - Exporting the following env vars:
AIRFLOW_CTX_DAG_OWNER=ManuelMoyano
AIRFLOW_CTX_DAG_ID=ETL_redshift_docker_***
AIRFLOW_CTX_TASK_ID=transformar_data
AIRFLOW_CTX_EXECUTION_DATE=2023-12-05T00:00:00+00:00
AIRFLOW_CTX_TRY_NUMBER=2
AIRFLOW_CTX_DAG_RUN_ID=scheduled__2023-12-05T00:00:00+00:00
[2023-12-06 18:41:30,111] {logging_mixin.py:115} INFO - Transformando la data para la fecha: 2023-12-05 0
[2023-12-06 18:41:30,112] {taskinstance.py:1909} ERROR - Task failed with exception
Traceback (most recent call last):
  File "/home/airflow/.local/lib/python3.7/site-packages/airflow/operators/python.py", line 171, in execute
    return_value = self.execute_callable()
  File "/home/airflow/.local/lib/python3.7/site-packages/airflow/operators/python.py", line 189, in execute_callable
    return self.python_callable(*self.op_args, **self.op_kwargs)
  File "/opt/airflow/dags/ETL a Redshift.py", line 104, in transformar_data
    fullpage_movie = pages[f'df_movie_{1}']
KeyError: 'df_movie_1'
[2023-12-06 18:41:30,121] {taskinstance.py:1420} INFO - Marking task as UP_FOR_RETRY. dag_id=ETL_redshift_docker_***, task_id=transformar_data, execution_date=20231205T000000, start_date=20231206T184129, end_date=20231206T184130
[2023-12-06 18:41:30,130] {standard_task_runner.py:97} ERROR - Failed to execute job 50 for task transformar_data ('df_movie_1'; 388)
[2023-12-06 18:41:30,144] {local_task_job.py:156} INFO - Task exited with return code 1
[2023-12-06 18:41:30,179] {local_task_job.py:273} INFO - 0 downstream tasks scheduled from follow-on schedule check
