[2023-12-07 21:54:04,638] {taskinstance.py:1179} INFO - Dependencies all met for <TaskInstance: ETL_redshift_docker_airflow.extraer_data manual__2023-12-07T21:34:35.619321+00:00 [queued]>
[2023-12-07 21:54:04,664] {taskinstance.py:1179} INFO - Dependencies all met for <TaskInstance: ETL_redshift_docker_airflow.extraer_data manual__2023-12-07T21:34:35.619321+00:00 [queued]>
[2023-12-07 21:54:04,665] {taskinstance.py:1376} INFO - 
--------------------------------------------------------------------------------
[2023-12-07 21:54:04,666] {taskinstance.py:1377} INFO - Starting attempt 3 of 6
[2023-12-07 21:54:04,668] {taskinstance.py:1378} INFO - 
--------------------------------------------------------------------------------
[2023-12-07 21:54:04,700] {taskinstance.py:1397} INFO - Executing <Task(PythonOperator): extraer_data> on 2023-12-07 21:34:35.619321+00:00
[2023-12-07 21:54:04,707] {standard_task_runner.py:52} INFO - Started process 434 to run task
[2023-12-07 21:54:04,714] {standard_task_runner.py:79} INFO - Running: ['***', 'tasks', 'run', 'ETL_redshift_docker_***', 'extraer_data', 'manual__2023-12-07T21:34:35.619321+00:00', '--job-id', '120', '--raw', '--subdir', 'DAGS_FOLDER/ETL a Redshift.py', '--cfg-path', '/tmp/tmp1ibgklui', '--error-file', '/tmp/tmpnz18do3t']
[2023-12-07 21:54:04,717] {standard_task_runner.py:80} INFO - Job 120: Subtask extraer_data
[2023-12-07 21:54:04,825] {task_command.py:371} INFO - Running <TaskInstance: ETL_redshift_docker_airflow.extraer_data manual__2023-12-07T21:34:35.619321+00:00 [running]> on host 4357a10b93bd
[2023-12-07 21:54:04,874] {logging_mixin.py:115} WARNING - /home/***/.local/lib/python3.7/site-packages/***/utils/context.py:202 AirflowContextDeprecationWarning: Accessing 'execution_date' from the template is deprecated and will be removed in a future version. Please use 'data_interval_start' or 'logical_date' instead.
[2023-12-07 21:54:04,935] {taskinstance.py:1591} INFO - Exporting the following env vars:
AIRFLOW_CTX_DAG_OWNER=ManuelMoyano
AIRFLOW_CTX_DAG_ID=ETL_redshift_docker_***
AIRFLOW_CTX_TASK_ID=extraer_data
AIRFLOW_CTX_EXECUTION_DATE=2023-12-07T21:34:35.619321+00:00
AIRFLOW_CTX_TRY_NUMBER=3
AIRFLOW_CTX_DAG_RUN_ID=manual__2023-12-07T21:34:35.619321+00:00
[2023-12-07 21:54:04,938] {logging_mixin.py:115} INFO - Adquiriendo data para la fecha: 2023-12-07 21
[2023-12-07 21:54:07,635] {taskinstance.py:1909} ERROR - Task failed with exception
Traceback (most recent call last):
  File "/home/airflow/.local/lib/python3.7/site-packages/airflow/operators/python.py", line 171, in execute
    return_value = self.execute_callable()
  File "/home/airflow/.local/lib/python3.7/site-packages/airflow/operators/python.py", line 189, in execute_callable
    return self.python_callable(*self.op_args, **self.op_kwargs)
  File "/opt/airflow/dags/ETL a Redshift.py", line 111, in extraer_data
    with open(dag_path + '/raw_data/' + "data_" + str(now.year) + '-' + str(now.month) + '-' + str(now.day) + '-' + str(now.hour) + ".json", "w") as json_file:
FileNotFoundError: [Errno 2] No such file or directory: '/opt/airflow/raw_data/data_2023-12-7-21.json'
[2023-12-07 21:54:07,645] {taskinstance.py:1420} INFO - Marking task as UP_FOR_RETRY. dag_id=ETL_redshift_docker_***, task_id=extraer_data, execution_date=20231207T213435, start_date=20231207T215404, end_date=20231207T215407
[2023-12-07 21:54:07,659] {standard_task_runner.py:97} ERROR - Failed to execute job 120 for task extraer_data ([Errno 2] No such file or directory: '/opt/airflow/raw_data/data_2023-12-7-21.json'; 434)
[2023-12-07 21:54:07,694] {local_task_job.py:156} INFO - Task exited with return code 1
[2023-12-07 21:54:07,737] {local_task_job.py:273} INFO - 0 downstream tasks scheduled from follow-on schedule check
