[2023-12-07 22:15:29,503] {taskinstance.py:1179} INFO - Dependencies all met for <TaskInstance: ETL_redshift_docker_airflow.cargar_data manual__2023-12-07T22:15:17.479291+00:00 [queued]>
[2023-12-07 22:15:29,513] {taskinstance.py:1179} INFO - Dependencies all met for <TaskInstance: ETL_redshift_docker_airflow.cargar_data manual__2023-12-07T22:15:17.479291+00:00 [queued]>
[2023-12-07 22:15:29,514] {taskinstance.py:1376} INFO - 
--------------------------------------------------------------------------------
[2023-12-07 22:15:29,514] {taskinstance.py:1377} INFO - Starting attempt 1 of 6
[2023-12-07 22:15:29,514] {taskinstance.py:1378} INFO - 
--------------------------------------------------------------------------------
[2023-12-07 22:15:29,529] {taskinstance.py:1397} INFO - Executing <Task(PythonOperator): cargar_data> on 2023-12-07 22:15:17.479291+00:00
[2023-12-07 22:15:29,533] {standard_task_runner.py:52} INFO - Started process 794 to run task
[2023-12-07 22:15:29,536] {standard_task_runner.py:79} INFO - Running: ['***', 'tasks', 'run', 'ETL_redshift_docker_***', 'cargar_data', 'manual__2023-12-07T22:15:17.479291+00:00', '--job-id', '176', '--raw', '--subdir', 'DAGS_FOLDER/ETL a Redshift.py', '--cfg-path', '/tmp/tmpo55kfbdj', '--error-file', '/tmp/tmpu2d7j6vt']
[2023-12-07 22:15:29,537] {standard_task_runner.py:80} INFO - Job 176: Subtask cargar_data
[2023-12-07 22:15:29,592] {task_command.py:371} INFO - Running <TaskInstance: ETL_redshift_docker_airflow.cargar_data manual__2023-12-07T22:15:17.479291+00:00 [running]> on host 4357a10b93bd
[2023-12-07 22:15:29,633] {logging_mixin.py:115} WARNING - /home/***/.local/lib/python3.7/site-packages/***/utils/context.py:202 AirflowContextDeprecationWarning: Accessing 'execution_date' from the template is deprecated and will be removed in a future version. Please use 'data_interval_start' or 'logical_date' instead.
[2023-12-07 22:15:29,671] {taskinstance.py:1591} INFO - Exporting the following env vars:
AIRFLOW_CTX_DAG_OWNER=ManuelMoyano
AIRFLOW_CTX_DAG_ID=ETL_redshift_docker_***
AIRFLOW_CTX_TASK_ID=cargar_data
AIRFLOW_CTX_EXECUTION_DATE=2023-12-07T22:15:17.479291+00:00
AIRFLOW_CTX_TRY_NUMBER=1
AIRFLOW_CTX_DAG_RUN_ID=manual__2023-12-07T22:15:17.479291+00:00
[2023-12-07 22:15:29,672] {logging_mixin.py:115} INFO - Cargando la data para la fecha: 2023-12-07 22
[2023-12-07 22:15:31,943] {taskinstance.py:1909} ERROR - Task failed with exception
Traceback (most recent call last):
  File "/home/airflow/.local/lib/python3.7/site-packages/airflow/operators/python.py", line 171, in execute
    return_value = self.execute_callable()
  File "/home/airflow/.local/lib/python3.7/site-packages/airflow/operators/python.py", line 189, in execute_callable
    return self.python_callable(*self.op_args, **self.op_kwargs)
  File "/opt/airflow/dags/ETL a Redshift.py", line 185, in cargar_data
    psycopg2.connect.close()
AttributeError: 'function' object has no attribute 'close'
[2023-12-07 22:15:31,954] {taskinstance.py:1420} INFO - Marking task as UP_FOR_RETRY. dag_id=ETL_redshift_docker_***, task_id=cargar_data, execution_date=20231207T221517, start_date=20231207T221529, end_date=20231207T221531
[2023-12-07 22:15:32,018] {standard_task_runner.py:97} ERROR - Failed to execute job 176 for task cargar_data ('function' object has no attribute 'close'; 794)
[2023-12-07 22:15:32,039] {local_task_job.py:156} INFO - Task exited with return code 1
[2023-12-07 22:15:32,065] {local_task_job.py:273} INFO - 0 downstream tasks scheduled from follow-on schedule check
