[2023-12-07 21:34:24,324] {taskinstance.py:1179} INFO - Dependencies all met for <TaskInstance: ETL_redshift_docker_airflow.extraer_data manual__2023-12-06T19:22:17.782264+00:00 [queued]>
[2023-12-07 21:34:24,389] {taskinstance.py:1179} INFO - Dependencies all met for <TaskInstance: ETL_redshift_docker_airflow.extraer_data manual__2023-12-06T19:22:17.782264+00:00 [queued]>
[2023-12-07 21:34:24,392] {taskinstance.py:1376} INFO - 
--------------------------------------------------------------------------------
[2023-12-07 21:34:24,413] {taskinstance.py:1377} INFO - Starting attempt 5 of 6
[2023-12-07 21:34:24,414] {taskinstance.py:1378} INFO - 
--------------------------------------------------------------------------------
[2023-12-07 21:34:24,538] {taskinstance.py:1397} INFO - Executing <Task(PythonOperator): extraer_data> on 2023-12-06 19:22:17.782264+00:00
[2023-12-07 21:34:24,606] {standard_task_runner.py:52} INFO - Started process 300 to run task
[2023-12-07 21:34:24,627] {standard_task_runner.py:79} INFO - Running: ['***', 'tasks', 'run', 'ETL_redshift_docker_***', 'extraer_data', 'manual__2023-12-06T19:22:17.782264+00:00', '--job-id', '101', '--raw', '--subdir', 'DAGS_FOLDER/ETL a Redshift.py', '--cfg-path', '/tmp/tmpizrl9q6y', '--error-file', '/tmp/tmppihjgik7']
[2023-12-07 21:34:24,694] {standard_task_runner.py:80} INFO - Job 101: Subtask extraer_data
[2023-12-07 21:34:25,635] {task_command.py:371} INFO - Running <TaskInstance: ETL_redshift_docker_airflow.extraer_data manual__2023-12-06T19:22:17.782264+00:00 [running]> on host 4357a10b93bd
[2023-12-07 21:34:26,404] {logging_mixin.py:115} WARNING - /home/***/.local/lib/python3.7/site-packages/***/utils/context.py:202 AirflowContextDeprecationWarning: Accessing 'execution_date' from the template is deprecated and will be removed in a future version. Please use 'data_interval_start' or 'logical_date' instead.
[2023-12-07 21:34:26,868] {taskinstance.py:1591} INFO - Exporting the following env vars:
AIRFLOW_CTX_DAG_OWNER=ManuelMoyano
AIRFLOW_CTX_DAG_ID=ETL_redshift_docker_***
AIRFLOW_CTX_TASK_ID=extraer_data
AIRFLOW_CTX_EXECUTION_DATE=2023-12-06T19:22:17.782264+00:00
AIRFLOW_CTX_TRY_NUMBER=5
AIRFLOW_CTX_DAG_RUN_ID=manual__2023-12-06T19:22:17.782264+00:00
[2023-12-07 21:34:26,895] {logging_mixin.py:115} INFO - Adquiriendo data para la fecha: 2023-12-06 19
[2023-12-07 21:34:30,836] {taskinstance.py:1909} ERROR - Task failed with exception
Traceback (most recent call last):
  File "/home/airflow/.local/lib/python3.7/site-packages/airflow/operators/python.py", line 171, in execute
    return_value = self.execute_callable()
  File "/home/airflow/.local/lib/python3.7/site-packages/airflow/operators/python.py", line 189, in execute_callable
    return self.python_callable(*self.op_args, **self.op_kwargs)
  File "/opt/airflow/dags/ETL a Redshift.py", line 97, in extraer_data
    data_as_dict = pages.to_dict(orient='records')
AttributeError: 'dict' object has no attribute 'to_dict'
[2023-12-07 21:34:30,854] {taskinstance.py:1420} INFO - Marking task as UP_FOR_RETRY. dag_id=ETL_redshift_docker_***, task_id=extraer_data, execution_date=20231206T192217, start_date=20231207T213424, end_date=20231207T213430
[2023-12-07 21:34:31,515] {standard_task_runner.py:97} ERROR - Failed to execute job 101 for task extraer_data ('dict' object has no attribute 'to_dict'; 300)
[2023-12-07 21:34:31,577] {local_task_job.py:156} INFO - Task exited with return code 1
[2023-12-07 21:34:31,914] {local_task_job.py:273} INFO - 0 downstream tasks scheduled from follow-on schedule check
