[2023-12-20 14:23:05,854] {taskinstance.py:1032} INFO - Dependencies all met for <TaskInstance: ETL_redshift_docker_airflow.extraer_data manual__2023-12-20T14:23:01.828767+00:00 [queued]>
[2023-12-20 14:23:05,871] {taskinstance.py:1032} INFO - Dependencies all met for <TaskInstance: ETL_redshift_docker_airflow.extraer_data manual__2023-12-20T14:23:01.828767+00:00 [queued]>
[2023-12-20 14:23:05,871] {taskinstance.py:1238} INFO - 
--------------------------------------------------------------------------------
[2023-12-20 14:23:05,872] {taskinstance.py:1239} INFO - Starting attempt 1 of 6
[2023-12-20 14:23:05,872] {taskinstance.py:1240} INFO - 
--------------------------------------------------------------------------------
[2023-12-20 14:23:06,082] {taskinstance.py:1259} INFO - Executing <Task(PythonOperator): extraer_data> on 2023-12-20 14:23:01.828767+00:00
[2023-12-20 14:23:06,089] {standard_task_runner.py:52} INFO - Started process 417 to run task
[2023-12-20 14:23:06,093] {standard_task_runner.py:76} INFO - Running: ['***', 'tasks', 'run', 'ETL_redshift_docker_***', 'extraer_data', 'manual__2023-12-20T14:23:01.828767+00:00', '--job-id', '217', '--raw', '--subdir', 'DAGS_FOLDER/ETL a Redshift.py', '--cfg-path', '/tmp/tmp5_a4ggup', '--error-file', '/tmp/tmpcekzz00z']
[2023-12-20 14:23:06,094] {standard_task_runner.py:77} INFO - Job 217: Subtask extraer_data
[2023-12-20 14:23:06,629] {logging_mixin.py:109} INFO - Running <TaskInstance: ETL_redshift_docker_***.extraer_data manual__2023-12-20T14:23:01.828767+00:00 [running]> on host 1e42c6100bb8
[2023-12-20 14:23:06,657] {taskinstance.py:1700} ERROR - Task failed with exception
Traceback (most recent call last):
  File "/home/airflow/.local/lib/python3.6/site-packages/sqlalchemy/engine/base.py", line 1277, in _execute_context
    cursor, statement, parameters, context
  File "/home/airflow/.local/lib/python3.6/site-packages/sqlalchemy/engine/default.py", line 608, in do_execute
    cursor.execute(statement, parameters)
psycopg2.errors.UndefinedColumn: column xcom.execution_date does not exist
LINE 1: ...er_***' AND xcom.task_id = 'extraer_data' AND xcom.execu...
                                                             ^


The above exception was the direct cause of the following exception:

Traceback (most recent call last):
  File "/home/airflow/.local/lib/python3.6/site-packages/airflow/models/taskinstance.py", line 1329, in _run_raw_task
    self._execute_task_with_callbacks(context)
  File "/home/airflow/.local/lib/python3.6/site-packages/airflow/models/taskinstance.py", line 1415, in _execute_task_with_callbacks
    self.clear_xcom_data()
  File "/home/airflow/.local/lib/python3.6/site-packages/airflow/utils/session.py", line 70, in wrapper
    return func(*args, session=session, **kwargs)
  File "/home/airflow/.local/lib/python3.6/site-packages/airflow/models/taskinstance.py", line 792, in clear_xcom_data
    session=session,
  File "/home/airflow/.local/lib/python3.6/site-packages/airflow/utils/session.py", line 67, in wrapper
    return func(*args, **kwargs)
  File "/home/airflow/.local/lib/python3.6/site-packages/airflow/models/xcom.py", line 323, in clear
    return query.delete()
  File "/home/airflow/.local/lib/python3.6/site-packages/sqlalchemy/orm/query.py", line 3926, in delete
    delete_op.exec_()
  File "/home/airflow/.local/lib/python3.6/site-packages/sqlalchemy/orm/persistence.py", line 1697, in exec_
    self._do_exec()
  File "/home/airflow/.local/lib/python3.6/site-packages/sqlalchemy/orm/persistence.py", line 1930, in _do_exec
    self._execute_stmt(delete_stmt)
  File "/home/airflow/.local/lib/python3.6/site-packages/sqlalchemy/orm/persistence.py", line 1702, in _execute_stmt
    self.result = self.query._execute_crud(stmt, self.mapper)
  File "/home/airflow/.local/lib/python3.6/site-packages/sqlalchemy/orm/query.py", line 3568, in _execute_crud
    return conn.execute(stmt, self._params)
  File "/home/airflow/.local/lib/python3.6/site-packages/sqlalchemy/engine/base.py", line 1011, in execute
    return meth(self, multiparams, params)
  File "/home/airflow/.local/lib/python3.6/site-packages/sqlalchemy/sql/elements.py", line 298, in _execute_on_connection
    return connection._execute_clauseelement(self, multiparams, params)
  File "/home/airflow/.local/lib/python3.6/site-packages/sqlalchemy/engine/base.py", line 1130, in _execute_clauseelement
    distilled_params,
  File "/home/airflow/.local/lib/python3.6/site-packages/sqlalchemy/engine/base.py", line 1317, in _execute_context
    e, statement, parameters, cursor, context
  File "/home/airflow/.local/lib/python3.6/site-packages/sqlalchemy/engine/base.py", line 1511, in _handle_dbapi_exception
    sqlalchemy_exception, with_traceback=exc_info[2], from_=e
  File "/home/airflow/.local/lib/python3.6/site-packages/sqlalchemy/util/compat.py", line 182, in raise_
    raise exception
  File "/home/airflow/.local/lib/python3.6/site-packages/sqlalchemy/engine/base.py", line 1277, in _execute_context
    cursor, statement, parameters, context
  File "/home/airflow/.local/lib/python3.6/site-packages/sqlalchemy/engine/default.py", line 608, in do_execute
    cursor.execute(statement, parameters)
sqlalchemy.exc.ProgrammingError: (psycopg2.errors.UndefinedColumn) column xcom.execution_date does not exist
LINE 1: ...er_***' AND xcom.task_id = 'extraer_data' AND xcom.execu...
                                                             ^

[SQL: DELETE FROM xcom WHERE xcom.dag_id = %(dag_id_1)s AND xcom.task_id = %(task_id_1)s AND xcom.execution_date = %(execution_date_1)s]
[parameters: {'dag_id_1': 'ETL_redshift_docker_airflow', 'task_id_1': 'extraer_data', 'execution_date_1': datetime.datetime(2023, 12, 20, 14, 23, 1, 828767, tzinfo=Timezone('UTC'))}]
(Background on this error at: http://sqlalche.me/e/13/f405)
[2023-12-20 14:23:06,669] {taskinstance.py:1277} INFO - Marking task as UP_FOR_RETRY. dag_id=ETL_redshift_docker_***, task_id=extraer_data, execution_date=20231220T142301, start_date=20231220T142305, end_date=20231220T142306
[2023-12-20 14:23:06,679] {standard_task_runner.py:92} ERROR - Failed to execute job 217 for task extraer_data
Traceback (most recent call last):
  File "/home/airflow/.local/lib/python3.6/site-packages/sqlalchemy/engine/base.py", line 1277, in _execute_context
    cursor, statement, parameters, context
  File "/home/airflow/.local/lib/python3.6/site-packages/sqlalchemy/engine/default.py", line 608, in do_execute
    cursor.execute(statement, parameters)
psycopg2.errors.UndefinedColumn: column xcom.execution_date does not exist
LINE 1: ...er_***' AND xcom.task_id = 'extraer_data' AND xcom.execu...
                                                             ^


The above exception was the direct cause of the following exception:

Traceback (most recent call last):
  File "/home/airflow/.local/lib/python3.6/site-packages/airflow/models/taskinstance.py", line 1329, in _run_raw_task
    self._execute_task_with_callbacks(context)
  File "/home/airflow/.local/lib/python3.6/site-packages/airflow/models/taskinstance.py", line 1415, in _execute_task_with_callbacks
    self.clear_xcom_data()
  File "/home/airflow/.local/lib/python3.6/site-packages/airflow/utils/session.py", line 70, in wrapper
    return func(*args, session=session, **kwargs)
  File "/home/airflow/.local/lib/python3.6/site-packages/airflow/models/taskinstance.py", line 792, in clear_xcom_data
    session=session,
  File "/home/airflow/.local/lib/python3.6/site-packages/airflow/utils/session.py", line 67, in wrapper
    return func(*args, **kwargs)
  File "/home/airflow/.local/lib/python3.6/site-packages/airflow/models/xcom.py", line 323, in clear
    return query.delete()
  File "/home/airflow/.local/lib/python3.6/site-packages/sqlalchemy/orm/query.py", line 3926, in delete
    delete_op.exec_()
  File "/home/airflow/.local/lib/python3.6/site-packages/sqlalchemy/orm/persistence.py", line 1697, in exec_
    self._do_exec()
  File "/home/airflow/.local/lib/python3.6/site-packages/sqlalchemy/orm/persistence.py", line 1930, in _do_exec
    self._execute_stmt(delete_stmt)
  File "/home/airflow/.local/lib/python3.6/site-packages/sqlalchemy/orm/persistence.py", line 1702, in _execute_stmt
    self.result = self.query._execute_crud(stmt, self.mapper)
  File "/home/airflow/.local/lib/python3.6/site-packages/sqlalchemy/orm/query.py", line 3568, in _execute_crud
    return conn.execute(stmt, self._params)
  File "/home/airflow/.local/lib/python3.6/site-packages/sqlalchemy/engine/base.py", line 1011, in execute
    return meth(self, multiparams, params)
  File "/home/airflow/.local/lib/python3.6/site-packages/sqlalchemy/sql/elements.py", line 298, in _execute_on_connection
    return connection._execute_clauseelement(self, multiparams, params)
  File "/home/airflow/.local/lib/python3.6/site-packages/sqlalchemy/engine/base.py", line 1130, in _execute_clauseelement
    distilled_params,
  File "/home/airflow/.local/lib/python3.6/site-packages/sqlalchemy/engine/base.py", line 1317, in _execute_context
    e, statement, parameters, cursor, context
  File "/home/airflow/.local/lib/python3.6/site-packages/sqlalchemy/engine/base.py", line 1511, in _handle_dbapi_exception
    sqlalchemy_exception, with_traceback=exc_info[2], from_=e
  File "/home/airflow/.local/lib/python3.6/site-packages/sqlalchemy/util/compat.py", line 182, in raise_
    raise exception
  File "/home/airflow/.local/lib/python3.6/site-packages/sqlalchemy/engine/base.py", line 1277, in _execute_context
    cursor, statement, parameters, context
  File "/home/airflow/.local/lib/python3.6/site-packages/sqlalchemy/engine/default.py", line 608, in do_execute
    cursor.execute(statement, parameters)
sqlalchemy.exc.ProgrammingError: (psycopg2.errors.UndefinedColumn) column xcom.execution_date does not exist
LINE 1: ...er_***' AND xcom.task_id = 'extraer_data' AND xcom.execu...
                                                             ^

[SQL: DELETE FROM xcom WHERE xcom.dag_id = %(dag_id_1)s AND xcom.task_id = %(task_id_1)s AND xcom.execution_date = %(execution_date_1)s]
[parameters: {'dag_id_1': 'ETL_redshift_docker_airflow', 'task_id_1': 'extraer_data', 'execution_date_1': datetime.datetime(2023, 12, 20, 14, 23, 1, 828767, tzinfo=Timezone('UTC'))}]
(Background on this error at: http://sqlalche.me/e/13/f405)

During handling of the above exception, another exception occurred:

Traceback (most recent call last):
  File "/home/airflow/.local/lib/python3.6/site-packages/sqlalchemy/engine/base.py", line 1277, in _execute_context
    cursor, statement, parameters, context
  File "/home/airflow/.local/lib/python3.6/site-packages/sqlalchemy/engine/default.py", line 608, in do_execute
    cursor.execute(statement, parameters)
psycopg2.errors.UndefinedColumn: column "execution_date" of relation "task_fail" does not exist
LINE 1: INSERT INTO task_fail (task_id, dag_id, execution_date, star...
                                                ^


The above exception was the direct cause of the following exception:

Traceback (most recent call last):
  File "/home/airflow/.local/lib/python3.6/site-packages/airflow/task/task_runner/standard_task_runner.py", line 85, in _start_by_fork
    args.func(args, dag=self.dag)
  File "/home/airflow/.local/lib/python3.6/site-packages/airflow/cli/cli_parser.py", line 48, in command
    return func(*args, **kwargs)
  File "/home/airflow/.local/lib/python3.6/site-packages/airflow/utils/cli.py", line 92, in wrapper
    return f(*args, **kwargs)
  File "/home/airflow/.local/lib/python3.6/site-packages/airflow/cli/commands/task_command.py", line 298, in task_run
    _run_task_by_selected_method(args, dag, ti)
  File "/home/airflow/.local/lib/python3.6/site-packages/airflow/cli/commands/task_command.py", line 107, in _run_task_by_selected_method
    _run_raw_task(args, ti)
  File "/home/airflow/.local/lib/python3.6/site-packages/airflow/cli/commands/task_command.py", line 184, in _run_raw_task
    error_file=args.error_file,
  File "/home/airflow/.local/lib/python3.6/site-packages/airflow/utils/session.py", line 70, in wrapper
    return func(*args, session=session, **kwargs)
  File "/home/airflow/.local/lib/python3.6/site-packages/airflow/models/taskinstance.py", line 1386, in _run_raw_task
    self.handle_failure(e, test_mode, error_file=error_file, session=session)
  File "/home/airflow/.local/lib/python3.6/site-packages/airflow/utils/session.py", line 67, in wrapper
    return func(*args, **kwargs)
  File "/home/airflow/.local/lib/python3.6/site-packages/airflow/models/taskinstance.py", line 1755, in handle_failure
    session.flush()
  File "/home/airflow/.local/lib/python3.6/site-packages/sqlalchemy/orm/session.py", line 2540, in flush
    self._flush(objects)
  File "/home/airflow/.local/lib/python3.6/site-packages/sqlalchemy/orm/session.py", line 2682, in _flush
    transaction.rollback(_capture_exception=True)
  File "/home/airflow/.local/lib/python3.6/site-packages/sqlalchemy/util/langhelpers.py", line 70, in __exit__
    with_traceback=exc_tb,
  File "/home/airflow/.local/lib/python3.6/site-packages/sqlalchemy/util/compat.py", line 182, in raise_
    raise exception
  File "/home/airflow/.local/lib/python3.6/site-packages/sqlalchemy/orm/session.py", line 2642, in _flush
    flush_context.execute()
  File "/home/airflow/.local/lib/python3.6/site-packages/sqlalchemy/orm/unitofwork.py", line 422, in execute
    rec.execute(self)
  File "/home/airflow/.local/lib/python3.6/site-packages/sqlalchemy/orm/unitofwork.py", line 589, in execute
    uow,
  File "/home/airflow/.local/lib/python3.6/site-packages/sqlalchemy/orm/persistence.py", line 245, in save_obj
    insert,
  File "/home/airflow/.local/lib/python3.6/site-packages/sqlalchemy/orm/persistence.py", line 1136, in _emit_insert_statements
    statement, params
  File "/home/airflow/.local/lib/python3.6/site-packages/sqlalchemy/engine/base.py", line 1011, in execute
    return meth(self, multiparams, params)
  File "/home/airflow/.local/lib/python3.6/site-packages/sqlalchemy/sql/elements.py", line 298, in _execute_on_connection
    return connection._execute_clauseelement(self, multiparams, params)
  File "/home/airflow/.local/lib/python3.6/site-packages/sqlalchemy/engine/base.py", line 1130, in _execute_clauseelement
    distilled_params,
  File "/home/airflow/.local/lib/python3.6/site-packages/sqlalchemy/engine/base.py", line 1317, in _execute_context
    e, statement, parameters, cursor, context
  File "/home/airflow/.local/lib/python3.6/site-packages/sqlalchemy/engine/base.py", line 1511, in _handle_dbapi_exception
    sqlalchemy_exception, with_traceback=exc_info[2], from_=e
  File "/home/airflow/.local/lib/python3.6/site-packages/sqlalchemy/util/compat.py", line 182, in raise_
    raise exception
  File "/home/airflow/.local/lib/python3.6/site-packages/sqlalchemy/engine/base.py", line 1277, in _execute_context
    cursor, statement, parameters, context
  File "/home/airflow/.local/lib/python3.6/site-packages/sqlalchemy/engine/default.py", line 608, in do_execute
    cursor.execute(statement, parameters)
sqlalchemy.exc.ProgrammingError: (psycopg2.errors.UndefinedColumn) column "execution_date" of relation "task_fail" does not exist
LINE 1: INSERT INTO task_fail (task_id, dag_id, execution_date, star...
                                                ^

[SQL: INSERT INTO task_fail (task_id, dag_id, execution_date, start_date, end_date, duration) VALUES (%(task_id)s, %(dag_id)s, %(execution_date)s, %(start_date)s, %(end_date)s, %(duration)s) RETURNING task_fail.id]
[parameters: {'task_id': 'extraer_data', 'dag_id': 'ETL_redshift_docker_airflow', 'execution_date': datetime.datetime(2023, 12, 20, 14, 23, 1, 828767, tzinfo=Timezone('UTC')), 'start_date': datetime.datetime(2023, 12, 20, 14, 23, 5, 857143, tzinfo=Timezone('UTC')), 'end_date': datetime.datetime(2023, 12, 20, 14, 23, 6, 669460, tzinfo=Timezone('UTC')), 'duration': 0}]
(Background on this error at: http://sqlalche.me/e/13/f405)
[2023-12-20 14:23:06,988] {local_task_job.py:154} INFO - Task exited with return code 1
[2023-12-20 14:23:07,012] {taskinstance.py:1277} INFO - Marking task as UP_FOR_RETRY. dag_id=ETL_redshift_docker_***, task_id=extraer_data, execution_date=20231220T142301, start_date=20231220T142305, end_date=20231220T142307
