[2023-12-07 21:34:24,353] {taskinstance.py:1179} INFO - Dependencies all met for <TaskInstance: ETL_redshift_docker_airflow.extraer_data scheduled__2023-12-06T00:00:00+00:00 [queued]>
[2023-12-07 21:34:24,408] {taskinstance.py:1179} INFO - Dependencies all met for <TaskInstance: ETL_redshift_docker_airflow.extraer_data scheduled__2023-12-06T00:00:00+00:00 [queued]>
[2023-12-07 21:34:24,409] {taskinstance.py:1376} INFO - 
--------------------------------------------------------------------------------
[2023-12-07 21:34:24,413] {taskinstance.py:1377} INFO - Starting attempt 1 of 6
[2023-12-07 21:34:24,414] {taskinstance.py:1378} INFO - 
--------------------------------------------------------------------------------
[2023-12-07 21:34:24,522] {taskinstance.py:1397} INFO - Executing <Task(PythonOperator): extraer_data> on 2023-12-06 00:00:00+00:00
[2023-12-07 21:34:24,534] {standard_task_runner.py:52} INFO - Started process 297 to run task
[2023-12-07 21:34:24,616] {standard_task_runner.py:79} INFO - Running: ['***', 'tasks', 'run', 'ETL_redshift_docker_***', 'extraer_data', 'scheduled__2023-12-06T00:00:00+00:00', '--job-id', '104', '--raw', '--subdir', 'DAGS_FOLDER/ETL a Redshift.py', '--cfg-path', '/tmp/tmpectftn9k', '--error-file', '/tmp/tmpdhrbj1qn']
[2023-12-07 21:34:24,648] {standard_task_runner.py:80} INFO - Job 104: Subtask extraer_data
[2023-12-07 21:34:25,632] {task_command.py:371} INFO - Running <TaskInstance: ETL_redshift_docker_airflow.extraer_data scheduled__2023-12-06T00:00:00+00:00 [running]> on host 4357a10b93bd
[2023-12-07 21:34:26,685] {logging_mixin.py:115} WARNING - /home/***/.local/lib/python3.7/site-packages/***/utils/context.py:202 AirflowContextDeprecationWarning: Accessing 'execution_date' from the template is deprecated and will be removed in a future version. Please use 'data_interval_start' or 'logical_date' instead.
[2023-12-07 21:34:26,893] {taskinstance.py:1591} INFO - Exporting the following env vars:
AIRFLOW_CTX_DAG_OWNER=ManuelMoyano
AIRFLOW_CTX_DAG_ID=ETL_redshift_docker_***
AIRFLOW_CTX_TASK_ID=extraer_data
AIRFLOW_CTX_EXECUTION_DATE=2023-12-06T00:00:00+00:00
AIRFLOW_CTX_TRY_NUMBER=1
AIRFLOW_CTX_DAG_RUN_ID=scheduled__2023-12-06T00:00:00+00:00
[2023-12-07 21:34:26,901] {logging_mixin.py:115} INFO - Adquiriendo data para la fecha: 2023-12-06 0
[2023-12-07 21:34:30,588] {taskinstance.py:1909} ERROR - Task failed with exception
Traceback (most recent call last):
  File "/home/airflow/.local/lib/python3.7/site-packages/airflow/operators/python.py", line 171, in execute
    return_value = self.execute_callable()
  File "/home/airflow/.local/lib/python3.7/site-packages/airflow/operators/python.py", line 189, in execute_callable
    return self.python_callable(*self.op_args, **self.op_kwargs)
  File "/opt/airflow/dags/ETL a Redshift.py", line 97, in extraer_data
    data_as_dict = pages.to_dict(orient='records')
AttributeError: 'dict' object has no attribute 'to_dict'
[2023-12-07 21:34:30,614] {taskinstance.py:1420} INFO - Marking task as UP_FOR_RETRY. dag_id=ETL_redshift_docker_***, task_id=extraer_data, execution_date=20231206T000000, start_date=20231207T213424, end_date=20231207T213430
[2023-12-07 21:34:30,704] {standard_task_runner.py:97} ERROR - Failed to execute job 104 for task extraer_data ('dict' object has no attribute 'to_dict'; 297)
[2023-12-07 21:34:30,836] {local_task_job.py:156} INFO - Task exited with return code 1
[2023-12-07 21:34:31,512] {local_task_job.py:273} INFO - 0 downstream tasks scheduled from follow-on schedule check
